Workbook

Sheet Literatur
A1: Offene Verifikationen (J=TODO): | B1: =COUNTIF(Tabelle1[Seiten-Status],"TODO") -> 5 | D1: Ziel am 01.05.2026: 0 / 0 / n/n
A2: Verwaiste Quellen (O=Nein): | B2: =COUNTIF(Tabelle1[Im Dossier zitiert?],"Nein") -> 0
A3: Fortschritt (Final OK): | B3: =COUNTIF(Tabelle1[Final OK],"✓") & " / " & ROWS(Tabelle1[]) -> 0 / 67
A5: BibKey | B5: Frage | C5: Autor:in | D5: Jahr | E5: Titel (Kurz) | F5: Werktyp | G5: Auflage | H5: Seiten (bib) | I5: Seiten (verifiziert) | J5: Seiten-Status | K5: Standort | L5: Signatur/URL | M5: Prüfdatum | N5: Prüfer:in-Kürzel | O5: Im Dossier zitiert? | P5: Kritische Felder | Q5: Notiz | R5: Final OK
A6: stamm2021fehlenderblick | B6: FW1 | C6: Stamm | D6: 2021 | E6: Der fehlende Blick auf begabte Minoritäten | F6: Sammelband-Kap. | H6: 576--588 | I6: 10 | J6: TODO | O6: Prüfen | P6: Seiten | Q6: 576--587 vs. 576--588 (Review-Abweichung)
A7: kellerkoller2021hellekoepfe | B7: FW1 | C7: Keller-Koller | D7: 2021 | E7: Helle Köpfe mit Migrationshintergrund | F7: Sammelband-Kap. | H7: 76-- 78 | I7: 3 | J7: TODO | O7: Prüfen | P7: Seiten | Q7: Seitenbereich aus Huser (2021) nachschlagen und in .bib eintragen
A8: kellerkoller2009begabte | B8: FW1 | C8: Keller-Koller | D8: 2009 | E8: Begabte mit Migrationshintergrund (MA) | F8: Thesis | J8: n/a | O8: Prüfen | P8: keine | Q8: Masterarbeit FHNW
A9: maehler2018diagnostik | B9: FW1 | C9: Maehler, Shajek & Brinkmann (Hg.) | D9: 2018 | E9: Diagnostik bei Migrantinnen und Migranten | F9: Buch | J9: n/a | O9: Prüfen | P9: keine | Q9: Kap. 1–3, 9–10 (~80 S.)
A10: preckel2013hochbegabung | B10: FW1 | C10: Preckel & Baudson | D10: 2013 | E10: Hochbegabung: Erkennen, Verstehen, Fördern | F10: Buch | H10: 7--52 | I10: 46 | J10: n/a | O10: Prüfen | P10: keine | Q10: Kap. 1–2 (~40 S.)
A11: muelleroppliger2021handbuch | B11: FW1 | C11: Müller-Oppliger & Weigand (Hg.) | D11: 2021 | E11: Handbuch Begabung | F11: Buch | J11: n/a | O11: Prüfen | P11: keine | Q11: verteilt auf Fr.1 und 4 (~80 S.)
A12: trautmann2016einfuehrung | B12: FW1 | C12: Trautmann | D12: 2016 | E12: Einführung in die Hochbegabtenpädagogik | F12: Buch | G12: 3. Aufl. | H12: 27--77 | I12: 40 | J12: n/a | O12: Prüfen | P12: keine | Q12: Kap. 1–2 (~40 S.)
A13: reutlinger2015hochbegabung | B13: FW1 | C13: Reutlinger, Leana-Tascilar & Ziegler | D13: 2015 | E13: Hochbegabung und Migrationshintergrund | F13: Buch | H13: 11--22 | I13: 12 | J13: n/a | O13: Prüfen | P13: keine | Q13: FAU Erlangen-Nürnberg (~15 S.)
A14: ipege2009professionelle | B14: FW1 | C14: iPEGE (Hg.) | D14: 2009 | E14: Professionelle Begabtenförderung | F14: Buch | H14: 21--43 | I14: 23 | J14: n/a | O14: Prüfen | P14: keine | Q14: özbf Salzburg, Kap. Diagnostik (~20 S.)
A15: uslucan2012begabung | B15: FW1 | C15: Uslucan | D15: 2012 | E15: Begabung und Migration | F15: Online | J15: n/a | O15: Prüfen | P15: keine | Q15: Vortrag Münster 13.09.2012
A16: stamm2014handbuch | B16: FW1 | C16: Stamm (Hg.) | D16: 2014 | E16: Handbuch Talententwicklung | F16: Buch | J16: n/a | O16: Prüfen | P16: keine | Q16: Kap. Underachievement/Migration (~40 S.)
A17: webb2020doppeldiagnosen | B17: FW1 | C17: Webb et al. | D17: 2020 | E17: Doppeldiagnosen und Fehldiagnosen bei Hochbegabung | F17: Buch | G17: 2. Aufl. | J17: n/a | O17: Prüfen | P17: keine | Q17: dt. Übers. der 3. Aufl. (~25 S.)
A18: rosebrock2010grundlagen | B18: FW2 | C18: Rosebrock & Nix | D18: 2010 | E18: Grundlagen der Lesedidaktik | F18: Buch | G18: 3. Aufl. | J18: n/a | O18: Prüfen | P18: keine | Q18: Kap. 1–4 (~60 S.)
A19: gold2018lesenkannmanlernen | B19: FW2 | C19: Gold | D19: 2018 | E19: Lesen kann man lernen | F19: Buch | G19: 3. Aufl. | J19: n/a | O19: Prüfen | P19: keine | Q19: Kap. 1–4 (~70 S.)
A20: lehwald2017motivation | B20: FW2 | C20: Lehwald | D20: 2017 | E20: Motivation trifft Begabung | F20: Buch | J20: n/a | O20: Prüfen | P20: keine | Q20: Kap. 2–6, verteilt auf Fr.2/3 (~90 S.)
A21: fischer2020begabungsfoerderung | B21: FW2 | C21: Fischer et al. (Hg.) | D21: 2020 | E21: Begabungsförderung, Leistungsentwicklung, Bildungsgerechtigkeit | F21: Buch | G21: Band 10 | H21: 253--267 | I21: 15 | J21: n/a | O21: Prüfen | P21: keine | Q21: Band 2, verteilt auf Fr.1/2/4 (~60 S.)
A22: sturm2016graphomotorik | B22: FW2 | C22: Sturm | D22: 2016 | E22: Zur Bedeutung der graphomotorischen Prozesse | F22: Sammelband-Kap. | H22: 183--198 | J22: n/a | O22: Prüfen | P22: keine | Q22: 16 S.
A23: grossrieder2010anerkennung | B23: FW3 | C23: Grossrieder | D23: 2010 | E23: Gleiches und Unterschiedliches anerkennen | F23: Sammelband-Kap. | H23: 87--96 | J23: n/a | O23: Prüfen | P23: keine | Q23: 10 S.
A24: kuhl2019diversitaet | B24: FW3 | C24: Kuhl & Hofmann | D24: 2019 | E24: Diversität und Persönlichkeit | F24: Sammelband-Kap. | H24: 35--57 | J24: TODO | O24: Prüfen | P24: Seiten | Q24: 35--57 vs. 35--59 (Review-Abweichung)
A25: behrensen2019inklusive | B25: FW3 | C25: Behrensen | D25: 2019 | E25: Inklusive Begabungsförderung | F25: Sammelband-Kap. | H25: 86--98 | J25: n/a | O25: Prüfen | P25: keine | Q25: 13 S.
A26: booth2019index | B26: FW3 | C26: Booth & Ainscow | D26: 2019 | E26: Index für Inklusion | F26: Buch | G26: 2. Aufl. | J26: n/a | O26: Prüfen | P26: keine | Q26: Dimensionen A–C, Fr.3/4 (~90 S.)
A27: stamm2012migranten | B27: FW3 | C27: Stamm | D27: 2012 | E27: Migranten mit Potenzial | F27: Buch | J27: n/a | O27: Prüfen | P27: keine | Q27: Dossier 12/4 SWISSEducation (~15 S.)
A28: kappus2010migration | B28: FW3 | C28: Kappus | D28: 2010 | E28: Umgang mit migrationsbedingter Heterogenität | F28: Sammelband-Kap. | H28: 63--77 | I28: 14 | J28: n/a | O28: Prüfen | P28: keine | Q28: 15 S.
A29: buholzer2010allegleich | B29: BW4 | C29: Buholzer & Kummer Wyss (Hg.) | D29: 2010 | E29: Alle gleich – alle unterschiedlich! | F29: Buch | J29: n/a | O29: Prüfen | P29: keine | Q29: verteilt auf Fr.4/5 (~60 S.)
A30: weigand2021separativ | B30: BW4 | C30: Weigand & Kaiser | D30: 2021 | E30: Separativ oder integrativ? | F30: Sammelband-Kap. | H30: 290--301 | J30: n/a | O30: Prüfen | P30: keine | Q30: ~15 S.
A31: sedmak2021bildungsgerechtigkeit | B31: BW4 | C31: Sedmak & Kapferer | D31: 2021 | E31: Begabtenförderung und Bildungsgerechtigkeit | F31: Sammelband-Kap. | H31: 65--76 | I31: 11 | J31: n/a | O31: Prüfen | P31: keine | Q31: ~15 S.
A32: muelleroppliger2021plurale | B32: BW4 | C32: Müller-Oppliger | D32: 2021 | E32: Plurale Gesellschaft, Inklusion, Bildungsgerechtigkeit | F32: Sammelband-Kap. | H32: 32--45 | J32: n/a | O32: Prüfen | P32: keine | Q32: ~15 S.
A33: unger2010begabungsfoerderung | B33: BW4 | C33: Unger | D33: 2010 | E33: Begabungs- und Begabtenförderung NMS | F33: Thesis | J33: n/a | O33: Prüfen | P33: keine | Q33: MA Univ. Salzburg/özbf (~20 S.)
A34: brunner2021hochbegabung | B34: BW4 | C34: Brunner, Gyseler & Lienhard | D34: 2021 | E34: Hochbegabung (k)ein Problem? | F34: Buch | G34: 3. Aufl. | J34: TODO | O34: Prüfen | P34: Auflage | Q34: 3. Aufl. 2021 vs. 1. Aufl. 2005 (Klett und Balmer, Zug) — ggf. .bib korrigieren
A35: burow2021positive | B35: BW5 | C35: Burow | D35: 2021 | E35: Positive Pädagogik | F35: Buch | G35: 2. Aufl. | J35: n/a | O35: Prüfen | P35: keine | Q35: ~50 S.
A36: burow2020future | B36: BW5 | C36: Burow | D36: 2020 | E36: Future Fridays | F36: Buch | J36: n/a | O36: Prüfen | P36: keine | Q36: ~30 S.
A37: leikhof2021jugendliche | B37: BW5 | C37: Leikhof | D37: 2021 | E37: Jugendliche mit Migrationshintergrund in der Begabungsförderung | F37: Thesis | J37: n/a | O37: Prüfen | P37: keine | Q37: Diss. Uni Köln, Kap. 1–3 (~60 S.)
A38: kosoroklabhart2021voneltern | B38: BW5 | C38: Košorok Labhart, Schöllhorn & Luginbühl | D38: 2021 | E38: Von Eltern mit Migrationshintergrund lernen | F38: Buch | J38: n/a | O38: Prüfen | P38: keine | Q38: ~30 S.
A39: macha2019gender | B39: BW5 | C39: Macha | D39: 2019 | E39: Gender und diversitätssensible Begabungsförderung | F39: Sammelband-Kap. | H39: 160--172 | J39: TODO | O39: Prüfen | P39: Seiten | Q39: 160--172 vs. 160--173 (Review-Abweichung)
A40: bfs2022migration | B40: Kontext | C40: Bundesamt für Statistik BFS | D40: 2022 | E40: Migration und Integration | F40: Report | J40: n/a | O40: Prüfen | P40: keine | Q40: BFS Neuchâtel
A41: erzinger2023pisa | B41: Kontext | C41: Erzinger, Pham, Prosperi & Salvisberg | D41: 2023 | E41: PISA 2022: Die Schweiz im Fokus | F41: Report | J41: n/a | O41: Prüfen | P41: keine | Q41: Univ. Bern
...

Sheet Zitatabgleich
A1: BibKey | B1: \cite-Treffer im Dossier | C1: Status
A2: =Literatur!A6 -> stamm2021fehlenderblick | C2: =IF(B2="","TODO",IF(B2=0,"NICHT ZITIERT","OK")) -> TODO
A3: =Literatur!A7 -> kellerkoller2021hellekoepfe | C3: =IF(B3="","TODO",IF(B3=0,"NICHT ZITIERT","OK")) -> TODO
A4: =Literatur!A8 -> kellerkoller2009begabte | C4: =IF(B4="","TODO",IF(B4=0,"NICHT ZITIERT","OK")) -> TODO
A5: =Literatur!A9 -> maehler2018diagnostik | C5: =IF(B5="","TODO",IF(B5=0,"NICHT ZITIERT","OK")) -> TODO
A6: =Literatur!A10 -> preckel2013hochbegabung | C6: =IF(B6="","TODO",IF(B6=0,"NICHT ZITIERT","OK")) -> TODO
A7: =Literatur!A11 -> muelleroppliger2021handbuch | C7: =IF(B7="","TODO",IF(B7=0,"NICHT ZITIERT","OK")) -> TODO
A8: =Literatur!A12 -> trautmann2016einfuehrung | C8: =IF(B8="","TODO",IF(B8=0,"NICHT ZITIERT","OK")) -> TODO
A9: =Literatur!A13 -> reutlinger2015hochbegabung | C9: =IF(B9="","TODO",IF(B9=0,"NICHT ZITIERT","OK")) -> TODO
A10: =Literatur!A14 -> ipege2009professionelle | C10: =IF(B10="","TODO",IF(B10=0,"NICHT ZITIERT","OK")) -> TODO
A11: =Literatur!A15 -> uslucan2012begabung | C11: =IF(B11="","TODO",IF(B11=0,"NICHT ZITIERT","OK")) -> TODO
A12: =Literatur!A16 -> stamm2014handbuch | C12: =IF(B12="","TODO",IF(B12=0,"NICHT ZITIERT","OK")) -> TODO
A13: =Literatur!A17 -> webb2020doppeldiagnosen | C13: =IF(B13="","TODO",IF(B13=0,"NICHT ZITIERT","OK")) -> TODO
... A46: =Literatur!A50 -> alodat2025equitable | C46: =IF(B46="","TODO",IF(B46=0,"NICHT ZITIERT","OK")) -> TODO

Sheet Listen
A1: Frage | B1: Werktyp | C1: Seiten-Status | D1: Standort | E1: Im Dossier zitiert? | F1: Kritische Felder | G1: Final OK
A2: FW1 | B2: Buch | C2: OK | D2: ZHB | E2: Ja | F2: keine | G2: ☐
A3: FW2 | B3: Sammelband-Kap. | C3: Abweichung | D3: eigenes Regal | E3: Nein | F3: Auflage | G3: ✓
A4: FW3 | B4: Zeitschrift | C4: TODO | D4: PDF | E4: Prüfen | F4: Jahr
A5: BW4 | B5: Online | C5: n/a | D5: Fernleihe | F5: Verlag
A6: BW5 | B6: Thesis | D6: fehlt | F6: Seiten
A7: Kontext | B7: Report | F7: Autor:in
